Workbook
Name Slicer_Product_Name: #N/A

Sheet Data
A1: Order ID | B1: Order Date | C1: Customer Name | D1: City | E1: Product Name | F1: Unit Price | G1: Quantity | H1: Discount (%) | I1: Subtotal | J1: Discount Amount | K1: Total Sales | L1: Shipping Fee | M1: Grand Total | N1: Payment Method | O1: Order Status | P1: Platform | Q1: Customer Rating | R1: Jenis Kelamin | S1: Category Rating | T1: Disc Category
A2: ORD00553 | B2: 45916.723 | C2: Kartika Saputra | D2: Palu | E2: Gula Pasir - Brand A | F2: 16000 | G2: 5 | H2: 10 | I2: =F2*G2 -> 80000 | J2: =I2*H2/100 -> 8000 | K2: =I2-J2 -> 72000 | L2: 67000 | M2: =Table1[[#This Row],[Total Sales]]+Table1[[#This Row],[Shipping Fee]] -> 139000 | N2: Kartu Kredit | O2: =VLOOKUP(Table1[[#This Row],[Order ID]],Status!A:B, 2,FALSE) -> Shipped | P2: Toko Biru | Q2: 3 | R2: Perempuan | S2: =_xlfn.IFS(Q2>3,"Bagus",Q2=3,"Standar",Q2<3,"Rendah") -> Standar | T2: =_xlfn.IFS(J2<=5000,"Sangat Rendah", J2<=10000,"Rendah", J2<=20000, "Normal", J2<=35000, "Tinggi", J2<= 50000, "Sangat Tinggi", J2>50000, "Clearance") -> Rendah
A3: ORD00700 | B3: 45916.459 | C3: Yani Kusuma | D3: Kendari | E3: Gula Pasir - Brand B | F3: 17000 | G3: 1 | H3: 0 | I3: =F3*G3 -> 17000 | J3: =I3*H3/100 -> 0 | K3: =I3-J3 -> 17000 | L3: 59000 | M3: =Table1[[#This Row],[Total Sales]]+Table1[[#This Row],[Shipping Fee]] -> 76000 | N3: COD | O3: =VLOOKUP(Table1[[#This Row],[Order ID]],Status!A:B, 2,FALSE) -> Pending | P3: Toko Ungu | Q3: 2 | R3: Perempuan | S3: =_xlfn.IFS(Q3>3,"Bagus",Q3=3,"Standar",Q3<3,"Rendah") -> Rendah | T3: =_xlfn.IFS(J3<=5000,"Sangat Rendah", J3<=10000,"Rendah", J3<=20000, "Normal", J3<=35000, "Tinggi", J3<= 50000, "Sangat Tinggi", J3>50000, "Clearance") -> Sangat Rendah | V3: =SUMIF(T:T,"Clearance",G:G) -> 10
A4: ORD01566 | B4: 45916.137 | C4: Qori Pradipta | D4: Tanjung Selor | E4: Garam - Brand B | F4: 5000 | G4: 1 | H4: 0 | I4: =F4*G4 -> 5000 | J4: =I4*H4/100 -> 0 | K4: =I4-J4 -> 5000 | L4: 26000 | M4: =Table1[[#This Row],[Total Sales]]+Table1[[#This Row],[Shipping Fee]] -> 31000 | N4: Kartu Kredit | O4: =VLOOKUP(Table1[[#This Row],[Order ID]],Status!A:B, 2,FALSE) -> Shipped | P4: Toko Ungu | Q4: 3 | R4: Perempuan | S4: =_xlfn.IFS(Q4>3,"Bagus",Q4=3,"Standar",Q4<3,"Rendah") -> Standar | T4: =_xlfn.IFS(J4<=5000,"Sangat Rendah", J4<=10000,"Rendah", J4<=20000, "Normal", J4<=35000, "Tinggi", J4<= 50000, "Sangat Tinggi", J4>50000, "Clearance") -> Sangat Rendah
A5: ORD00687 | B5: 45916.043 | C5: Oka Santoso | D5: Manokwari | E5: Beras - Brand A | F5: 14000 | G5: 4 | H5: 15 | I5: =F5*G5 -> 56000 | J5: =I5*H5/100 -> 8400 | K5: =I5-J5 -> 47600 | L5: 18000 | M5: =Table1[[#This Row],[Total Sales]]+Table1[[#This Row],[Shipping Fee]] -> 65600 | N5: COD | O5: =VLOOKUP(Table1[[#This Row],[Order ID]],Status!A:B, 2,FALSE) -> Completed | P5: Toko Orange | Q5: 1 | R5: Laki-laki | S5: =_xlfn.IFS(Q5>3,"Bagus",Q5=3,"Standar",Q5<3,"Rendah") -> Rendah | T5: =_xlfn.IFS(J5<=5000,"Sangat Rendah", J5<=10000,"Rendah", J5<=20000, "Normal", J5<=35000, "Tinggi", J5<= 50000, "Sangat Tinggi", J5>50000, "Clearance") -> Rendah
A6: ORD00755 | B6: 45915.817 | C6: Eka Pradipta | D6: Bandung | E6: Garam - Brand C | F6: 6000 | G6: 3 | H6: 20 | I6: =F6*G6 -> 18000 | J6: =I6*H6/100 -> 3600 | K6: =I6-J6 -> 14400 | L6: 0 | M6: =Table1[[#This Row],[Total Sales]]+Table1[[#This Row],[Shipping Fee]] -> 14400 | N6: Kartu Kredit | O6: =VLOOKUP(Table1[[#This Row],[Order ID]],Status!A:B, 2,FALSE) -> Pending | P6: TokTok | Q6: 3 | R6: Perempuan | S6: =_xlfn.IFS(Q6>3,"Bagus",Q6=3,"Standar",Q6<3,"Rendah") -> Standar | T6: =_xlfn.IFS(J6<=5000,"Sangat Rendah", J6<=10000,"Rendah", J6<=20000, "Normal", J6<=35000, "Tinggi", J6<= 50000, "Sangat Tinggi", J6>50000, "Clearance") -> Sangat Rendah | V6: =SUMIF(T:T,"Rendah",M:M) -> 46423250 | X6: Rata-rata quantity untuk kota Bandung :
A7: ORD00593 | B7: 45915.563 | C7: Aulia Utami | D7: Yogyakarta | E7: Garam - Brand C | F7: 6000 | G7: 3 | H7: 15 | I7: =F7*G7 -> 18000 | J7: =I7*H7/100 -> 2700 | K7: =I7-J7 -> 15300 | L7: 78000 | M7: =Table1[[#This Row],[Total Sales]]+Table1[[#This Row],[Shipping Fee]] -> 93300 | N7: Kartu Kredit | O7: =VLOOKUP(Table1[[#This Row],[Order ID]],Status!A:B, 2,FALSE) -> Completed | P7: TokTok | Q7: 2 | R7: Perempuan | S7: =_xlfn.IFS(Q7>3,"Bagus",Q7=3,"Standar",Q7<3,"Rendah") -> Rendah | T7: =_xlfn.IFS(J7<=5000,"Sangat Rendah", J7<=10000,"Rendah", J7<=20000, "Normal", J7<=35000, "Tinggi", J7<= 50000, "Sangat Tinggi", J7>50000, "Clearance") -> Sangat Rendah | X7: =AVERAGEIF(D:D,"Bandung",G:G) -> 2.8550725
A8: ORD00676 | B8: 45915.289 | C8: Dewi Wijaya | D8: Jayapura | E8: Susu Bubuk - Brand B | F8: 50000 | G8: 1 | H8: 10 | I8: =F8*G8 -> 50000 | J8: =I8*H8/100 -> 5000 | K8: =I8-J8 -> 45000 | L8: 30000 | M8: =Table1[[#This Row],[Total Sales]]+Table1[[#This Row],[Shipping Fee]] -> 75000 | N8: e-Wallet | O8: =VLOOKUP(Table1[[#This Row],[Order ID]],Status!A:B, 2,FALSE) -> Completed | P8: Toko Hijau | Q8: 4 | R8: Perempuan | S8: =_xlfn.IFS(Q8>3,"Bagus",Q8=3,"Standar",Q8<3,"Rendah") -> Bagus | T8: =_xlfn.IFS(J8<=5000,"Sangat Rendah", J8<=10000,"Rendah", J8<=20000, "Normal", J8<=35000, "Tinggi", J8<= 50000, "Sangat Tinggi", J8>50000, "Clearance") -> Sangat Rendah | V8: =AVERAGEIFS(Q:Q,R:R,"Perempuan",T:T,"Sangat Tinggi") -> 3.0416667
A9: ORD01797 | B9: 45915.262 | C9: Dina Halim | D9: Wamena | E9: Susu Bubuk - Brand C | F9: 55000 | G9: 4 | H9: 0 | I9: =F9*G9 -> 220000 | J9: =I9*H9/100 -> 0 | K9: =I9-J9 -> 220000 | L9: 15000 | M9: =Table1[[#This Row],[Total Sales]]+Table1[[#This Row],[Shipping Fee]] -> 235000 | N9: Transfer Bank | O9: =VLOOKUP(Table1[[#This Row],[Order ID]],Status!A:B, 2,FALSE) -> Pending | P9: Toko Orange | Q9: 5 | R9: Perempuan | S9: =_xlfn.IFS(Q9>3,"Bagus",Q9=3,"Standar",Q9<3,"Rendah") -> Bagus | T9: =_xlfn.IFS(J9<=5000,"Sangat Rendah", J9<=10000,"Rendah", J9<=20000, "Normal", J9<=35000, "Tinggi", J9<= 50000, "Sangat Tinggi", J9>50000, "Clearance") -> Sangat Rendah
A10: ORD01314 | B10: 45915.236 | C10: Bella Santoso | D10: Tanjung Selor | E10: Tepung Terigu - Brand B | F10: 12000 | G10: 2 | H10: 0 | I10: =F10*G10 -> 24000 | J10: =I10*H10/100 -> 0 | K10: =I10-J10 -> 24000 | L10: 26000 | M10: =Table1[[#This Row],[Total Sales]]+Table1[[#This Row],[Shipping Fee]] -> 50000 | N10: Transfer Bank | O10: =VLOOKUP(Table1[[#This Row],[Order ID]],Status!A:B, 2,FALSE) -> Cancelled | P10: Toko Hijau | Q10: 1 | R10: Perempuan | S10: =_xlfn.IFS(Q10>3,"Bagus",Q10=3,"Standar",Q10<3,"Rendah") -> Rendah | T10: =_xlfn.IFS(J10<=5000,"Sangat Rendah", J10<=10000,"Rendah", J10<=20000, "Normal", J10<=35000, "Tinggi", J10<= 50000, "Sangat Tinggi", J10>50000, "Clearance") -> Sangat Rendah | V10: Diskon | W10: kategori
A11: ORD00039 | B11: 45915.223 | C11: Andi Iskandar | D11: Jambi | E11: Tepung Terigu - Brand C | F11: 14000 | G11: 5 | H11: 20 | I11: =F11*G11 -> 70000 | J11: =I11*H11/100 -> 14000 | K11: =I11-J11 -> 56000 | L11: 87000 | M11: =Table1[[#This Row],[Total Sales]]+Table1[[#This Row],[Shipping Fee]] -> 143000 | N11: Kartu Kredit | O11: =VLOOKUP(Table1[[#This Row],[Order ID]],Status!A:B, 2,FALSE) -> Shipped | P11: Toko Orange | Q11: 3 | R11: Laki-laki | S11: =_xlfn.IFS(Q11>3,"Bagus",Q11=3,"Standar",Q11<3,"Rendah") -> Standar | T11: =_xlfn.IFS(J11<=5000,"Sangat Rendah", J11<=10000,"Rendah", J11<=20000, "Normal", J11<=35000, "Tinggi", J11<= 50000, "Sangat Tinggi", J11>50000, "Clearance") -> Normal | V11: 0 | W11: sangat rendah
A12: ORD00039 | B12: 45915.223 | C12: Andi Iskandar | D12: Jambi | E12: Daging Ayam - Brand A | F12: 35000 | G12: 3 | H12: 0 | I12: =F12*G12 -> 105000 | J12: =I12*H12/100 -> 0 | K12: =I12-J12 -> 105000 | L12: 0 | M12: =Table1[[#This Row],[Total Sales]]+Table1[[#This Row],[Shipping Fee]] -> 105000 | N12: Kartu Kredit | O12: =VLOOKUP(Table1[[#This Row],[Order ID]],Status!A:B, 2,FALSE) -> Shipped | P12: Toko Orange | Q12: 3 | R12: Laki-laki | S12: =_xlfn.IFS(Q12>3,"Bagus",Q12=3,"Standar",Q12<3,"Rendah") -> Standar | T12: =_xlfn.IFS(J12<=5000,"Sangat Rendah", J12<=10000,"Rendah", J12<=20000, "Normal", J12<=35000, "Tinggi", J12<= 50000, "Sangat Tinggi", J12>50000, "Clearance") -> Sangat Rendah | V12: 5001 | W12: rendah | X12: Jumlah total sales untuk pembayaran COD
A13: ORD00447 | B13: 45914.369 | C13: Dina Maulana | D13: Kupang | E13: Daging Ayam - Brand C | F13: 45000 | G13: 1 | H13: 10 | I13: =F13*G13 -> 45000 | J13: =I13*H13/100 -> 4500 | K13: =I13-J13 -> 40500 | L13: 21000 | M13: =Table1[[#This Row],[Total Sales]]+Table1[[#This Row],[Shipping Fee]] -> 61500 | N13: e-Wallet | O13: =VLOOKUP(Table1[[#This Row],[Order ID]],Status!A:B, 2,FALSE) -> Pending | P13: Toko Biru | Q13: 3 | R13: Perempuan | S13: =_xlfn.IFS(Q13>3,"Bagus",Q13=3,"Standar",Q13<3,"Rendah") -> Standar | T13: =_xlfn.IFS(J13<=5000,"Sangat Rendah", J13<=10000,"Rendah", J13<=20000, "Normal", J13<=35000, "Tinggi", J13<= 50000, "Sangat Tinggi", J13>50000, "Clearance") -> Sangat Rendah | V13: 10001 | W13: normal | X13: =SUMIF(N:N,"COD",K:K) -> 32878550
A14: ORD00860 | B14: 45913.935 | C14: Zahra Halim | D14: Jayapura | E14: Susu Bubuk - Brand B | F14: 50000 | G14: 3 | H14: 10 | I14: =F14*G14 -> 150000 | J14: =I14*H14/100 -> 15000 | K14: =I14-J14 -> 135000 | L14: 30000 | M14: =Table1[[#This Row],[Total Sales]]+Table1[[#This Row],[Shipping Fee]] -> 165000 | N14: Kartu Kredit | O14: =VLOOKUP(Table1[[#This Row],[Order ID]],Status!A:B, 2,FALSE) -> Completed | P14: Toko Hijau | Q14: 1 | R14: Perempuan | S14: =_xlfn.IFS(Q14>3,"Bagus",Q14=3,"Standar",Q14<3,"Rendah") -> Rendah | T14: =_xlfn.IFS(J14<=5000,"Sangat Rendah", J14<=10000,"Rendah", J14<=20000, "Normal", J14<=35000, "Tinggi", J14<= 50000, "Sangat Tinggi", J14>50000, "Clearance") -> Normal | V14: 20001 | W14: tinggi
A15: ORD00304 | B15: 45913.671 | C15: Zahra Ramadhani | D15: Makassar | E15: Bawang Merah - Brand A | F15: 30000 | G15: 5 | H15: 5 | I15: =F15*G15 -> 150000 | J15: =I15*H15/100 -> 7500 | K15: =I15-J15 -> 142500 | L15: 84000 | M15: =Table1[[#This Row],[Total Sales]]+Table1[[#This Row],[Shipping Fee]] -> 226500 | N15: COD | O15: =VLOOKUP(Table1[[#This Row],[Order ID]],Status!A:B, 2,FALSE) -> Completed | P15: Toko Biru | Q15: 1 | R15: Perempuan | S15: =_xlfn.IFS(Q15>3,"Bagus",Q15=3,"Standar",Q15<3,"Rendah") -> Rendah | T15: =_xlfn.IFS(J15<=5000,"Sangat Rendah", J15<=10000,"Rendah", J15<=20000, "Normal", J15<=35000, "Tinggi", J15<= 50000, "Sangat Tinggi", J15>50000, "Clearance") -> Rendah | V15: 35001 | W15: sangat tinggi
A16: ORD00147 | B16: 45913.319 | C16: Lestari Pradipta | D16: Mataram | E16: Telur Ayam - Brand B | F16: 25000 | G16: 3 | H16: 5 | I16: =F16*G16 -> 75000 | J16: =I16*H16/100 -> 3750 | K16: =I16-J16 -> 71250 | L16: 56000 | M16: =Table1[[#This Row],[Total Sales]]+Table1[[#This Row],[Shipping Fee]] -> 127250 | N16: e-Wallet | O16: =VLOOKUP(Table1[[#This Row],[Order ID]],Status!A:B, 2,FALSE) -> Pending | P16: Toko Hijau | Q16: 5 | R16: Perempuan | S16: =_xlfn.IFS(Q16>3,"Bagus",Q16=3,"Standar",Q16<3,"Rendah") -> Bagus | T16: =_xlfn.IFS(J16<=5000,"Sangat Rendah", J16<=10000,"Rendah", J16<=20000, "Normal", J16<=35000, "Tinggi", J16<= 50000, "Sangat Tinggi", J16>50000, "Clearance") -> Sangat Rendah | V16: 50001 | W16: mbuh
A17: ORD00299 | B17: 45913.297 | C17: Aulia Kusuma | D17: Surabaya | E17: Garam - Brand B | F17: 5000 | G17: 1 | H17: 10 | I17: =F17*G17 -> 5000 | J17: =I17*H17/100 -> 500 | K17: =I17-J17 -> 4500 | L17: 74000 | M17: =Table1[[#This Row],[Total Sales]]+Table1[[#This Row],[Shipping Fee]] -> 78500 | N17: e-Wallet | O17: =VLOOKUP(Table1[[#This Row],[Order ID]],Status!A:B, 2,FALSE) -> Completed | P17: Toko Ungu | Q17: 5 | R17: Perempuan | S17: =_xlfn.IFS(Q17>3,"Bagus",Q17=3,"Standar",Q17<3,"Rendah") -> Bagus | T17: =_xlfn.IFS(J17<=5000,"Sangat Rendah", J17<=10000,"Rendah", J17<=20000, "Normal", J17<=35000, "Tinggi", J17<= 50000, "Sangat Tinggi", J17>50000, "Clearance") -> Sangat Rendah | X17: Jenis platform yang tersedia
A18: ORD00192 | B18: 45913.279 | C18: Clara Halim | D18: Sorong | E18: Minyak Goreng - Brand B | F18: 17000 | G18: 5 | H18: 0 | I18: =F18*G18 -> 85000 | J18: =I18*H18/100 -> 0 | K18: =I18-J18 -> 85000 | L18: 87000 | M18: =Table1[[#This Row],[Total Sales]]+Table1[[#This Row],[Shipping Fee]] -> 172000 | N18: e-Wallet | O18: =VLOOKUP(Table1[[#This Row],[Order ID]],Status!A:B, 2,FALSE) -> Completed | P18: Toko Ungu | Q18: 2 | R18: Perempuan | S18: =_xlfn.IFS(Q18>3,"Bagus",Q18=3,"Standar",Q18<3,"Rendah") -> Rendah | T18: =_xlfn.IFS(J18<=5000,"Sangat Rendah", J18<=10000,"Rendah", J18<=20000, "Normal", J18<=35000, "Tinggi", J18<= 50000, "Sangat Tinggi", J18>50000, "Clearance") -> Sangat Rendah
A19: ORD00303 | B19: 45913.014 | C19: Ani Setiawan | D19: Mamuju | E19: Minyak Goreng - Brand B | F19: 17000 | G19: 3 | H19: 0 | I19: =F19*G19 -> 51000 | J19: =I19*H19/100 -> 0 | K19: =I19-J19 -> 51000 | L19: 46000 | M19: =Table1[[#This Row],[Total Sales]]+Table1[[#This Row],[Shipping Fee]] -> 97000 | N19: COD | O19: =VLOOKUP(Table1[[#This Row],[Order ID]],Status!A:B, 2,FALSE) -> Completed | P19: Toko Biru | Q19: 3 | R19: Perempuan | S19: =_xlfn.IFS(Q19>3,"Bagus",Q19=3,"Standar",Q19<3,"Rendah") -> Standar | T19: =_xlfn.IFS(J19<=5000,"Sangat Rendah", J19<=10000,"Rendah", J19<=20000, "Normal", J19<=35000, "Tinggi", J19<= 50000, "Sangat Tinggi", J19>50000, "Clearance") -> Sangat Rendah
A20: ORD00303 | B20: 45913.014 | C20: Ani Setiawan | D20: Mamuju | E20: Tepung Terigu - Brand C | F20: 14000 | G20: 4 | H20: 0 | I20: =F20*G20 -> 56000 | J20: =I20*H20/100 -> 0 | K20: =I20-J20 -> 56000 | L20: 0 | M20: =Table1[[#This Row],[Total Sales]]+Table1[[#This Row],[Shipping Fee]] -> 56000 | N20: COD | O20: =VLOOKUP(Table1[[#This Row],[Order ID]],Status!A:B, 2,FALSE) -> Completed | P20: Toko Biru | Q20: 3 | R20: Perempuan | S20: =_xlfn.IFS(Q20>3,"Bagus",Q20=3,"Standar",Q20<3,"Rendah") -> Standar | T20: =_xlfn.IFS(J20<=5000,"Sangat Rendah", J20<=10000,"Rendah", J20<=20000, "Normal", J20<=35000, "Tinggi", J20<= 50000, "Sangat Tinggi", J20>50000, "Clearance") -> Sangat Rendah
A21: ORD00027 | B21: 45913.006 | C21: Made Kusuma | D21: Makassar | E21: Gula Pasir - Brand B | F21: 17000 | G21: 5 | H21: 20 | I21: =F21*G21 -> 85000 | J21: =I21*H21/100 -> 17000 | K21: =I21-J21 -> 68000 | L21: 84000 | M21: =Table1[[#This Row],[Total Sales]]+Table1[[#This Row],[Shipping Fee]] -> 152000 | N21: Kartu Kredit | O21: =VLOOKUP(Table1[[#This Row],[Order ID]],Status!A:B, 2,FALSE) -> Completed | P21: Toko Orange | Q21: 5 | R21: Laki-laki | S21: =_xlfn.IFS(Q21>3,"Bagus",Q21=3,"Standar",Q21<3,"Rendah") -> Bagus | T21: =_xlfn.IFS(J21<=5000,"Sangat Rendah", J21<=10000,"Rendah", J21<=20000, "Normal", J21<=35000, "Tinggi", J21<= 50000, "Sangat Tinggi", J21>50000, "Clearance") -> Normal
A22: ORD00027 | B22: 45913.006 | C22: Made Kusuma | D22: Makassar | E22: Tepung Terigu - Brand B | F22: 12000 | G22: 4 | H22: 0 | I22: =F22*G22 -> 48000 | J22: =I22*H22/100 -> 0 | K22: =I22-J22 -> 48000 | L22: 0 | M22: =Table1[[#This Row],[Total Sales]]+Table1[[#This Row],[Shipping Fee]] -> 48000 | N22: Kartu Kredit | O22: =VLOOKUP(Table1[[#This Row],[Order ID]],Status!A:B, 2,FALSE) -> Completed | P22: Toko Orange | Q22: 5 | R22: Laki-laki | S22: =_xlfn.IFS(Q22>3,"Bagus",Q22=3,"Standar",Q22<3,"Rendah") -> Bagus | T22: =_xlfn.IFS(J22<=5000,"Sangat Rendah", J22<=10000,"Rendah", J22<=20000, "Normal", J22<=35000, "Tinggi", J22<= 50000, "Sangat Tinggi", J22>50000, "Clearance") -> Sangat Rendah | X22: Jumlah quantity yang termasuk kategoti clearance
A23: ORD01587 | B23: 45912.618 | C23: Lestari Puspita | D23: Yogyakarta | E23: Gula Pasir - Brand C | F23: 18000 | G23: 1 | H23: 0 | I23: =F23*G23 -> 18000 | J23: =I23*H23/100 -> 0 | K23: =I23-J23 -> 18000 | L23: 78000 | M23: =Table1[[#This Row],[Total Sales]]+Table1[[#This Row],[Shipping Fee]] -> 96000 | N23: Transfer Bank | O23: =VLOOKUP(Table1[[#This Row],[Order ID]],Status!A:B, 2,FALSE) -> Completed | P23: Toko Orange | Q23: 2 | R23: Perempuan | S23: =_xlfn.IFS(Q23>3,"Bagus",Q23=3,"Standar",Q23<3,"Rendah") -> Rendah | T23: =_xlfn.IFS(J23<=5000,"Sangat Rendah", J23<=10000,"Rendah", J23<=20000, "Normal", J23<=35000, "Tinggi", J23<= 50000, "Sangat Tinggi", J23>50000, "Clearance") -> Sangat Rendah | X23: =SUMIF(T:T,"Clearance",G:G) -> 10
A24: ORD01701 | B24: 45912.501 | C24: Qori Hidayat | D24: Palembang | E24: Susu Bubuk - Brand C | F24: 55000 | G24: 4 | H24: 20 | I24: =F24*G24 -> 220000 | J24: =I24*H24/100 -> 44000 | K24: =I24-J24 -> 176000 | L24: 17000 | M24: =Table1[[#This Row],[Total Sales]]+Table1[[#This Row],[Shipping Fee]] -> 193000 | N24: e-Wallet | O24: =VLOOKUP(Table1[[#This Row],[Order ID]],Status!A:B, 2,FALSE) -> Completed | P24: Toko Ungu | Q24: 4 | R24: Perempuan | S24: =_xlfn.IFS(Q24>3,"Bagus",Q24=3,"Standar",Q24<3,"Rendah") -> Bagus | T24: =_xlfn.IFS(J24<=5000,"Sangat Rendah", J24<=10000,"Rendah", J24<=20000, "Normal", J24<=35000, "Tinggi", J24<= 50000, "Sangat Tinggi", J24>50000, "Clearance") -> Sangat Tinggi
A25: ORD00168 | B25: 45912.45 | C25: Ani Ramadhani | D25: Sofifi | E25: Gula Pasir - Brand C | F25: 18000 | G25: 1 | H25: 10 | I25: =F25*G25 -> 18000 | J25: =I25*H25/100 -> 1800 | K25: =I25-J25 -> 16200 | L25: 50000 | M25: =Table1[[#This Row],[Total Sales]]+Table1[[#This Row],[Shipping Fee]] -> 66200 | N25: COD | O25: =VLOOKUP(Table1[[#This Row],[Order ID]],Status!A:B, 2,FALSE) -> Shipped | P25: Toko Ungu | Q25: 2 | R25: Perempuan | S25: =_xlfn.IFS(Q25>3,"Bagus",Q25=3,"Standar",Q25<3,"Rendah") -> Rendah | T25: =_xlfn.IFS(J25<=5000,"Sangat Rendah", J25<=10000,"Rendah", J25<=20000, "Normal", J25<=35000, "Tinggi", J25<= 50000, "Sangat Tinggi", J25>50000, "Clearance") -> Sangat Rendah
A26: ORD00659 | B26: 45912.353 | C26: Dewi Ananda | D26: Palangka Raya | E26: Daging Ayam - Brand C | F26: 45000 | G26: 2 | H26: 20 | I26: =F26*G26 -> 90000 | J26: =I26*H26/100 -> 18000 | K26: =I26-J26 -> 72000 | L26: 50000 | M26: =Table1[[#This Row],[Total Sales]]+Table1[[#This Row],[Shipping Fee]] -> 122000 | N26: e-Wallet | O26: =VLOOKUP(Table1[[#This Row],[Order ID]],Status!A:B, 2,FALSE) -> Completed | P26: TokTok | Q26: 5 | R26: Perempuan | S26: =_xlfn.IFS(Q26>3,"Bagus",Q26=3,"Standar",Q26<3,"Rendah") -> Bagus | T26: =_xlfn.IFS(J26<=5000,"Sangat Rendah", J26<=10000,"Rendah", J26<=20000, "Normal", J26<=35000, "Tinggi", J26<= 50000, "Sangat Tinggi", J26>50000, "Clearance") -> Normal | X26: Jumlah grand total untuk kategori rendah
A27: ORD00466 | B27: 45912.146 | C27: Ani Hidayat | D27: Samarinda | E27: Gula Pasir - Brand C | F27: 18000 | G27: 3 | H27: 20 | I27: =F27*G27 -> 54000 | J27: =I27*H27/100 -> 10800 | K27: =I27-J27 -> 43200 | L27: 43000 | M27: =Table1[[#This Row],[Total Sales]]+Table1[[#This Row],[Shipping Fee]] -> 86200 | N27: e-Wallet | O27: =VLOOKUP(Table1[[#This Row],[Order ID]],Status!A:B, 2,FALSE) -> Completed | P27: TokTok | Q27: 5 | R27: Perempuan | S27: =_xlfn.IFS(Q27>3,"Bagus",Q27=3,"Standar",Q27<3,"Rendah") -> Bagus | T27: =_xlfn.IFS(J27<=5000,"Sangat Rendah", J27<=10000,"Rendah", J27<=20000, "Normal", J27<=35000, "Tinggi", J27<= 50000, "Sangat Tinggi", J27>50000, "Clearance") -> Normal | X27: =SUMIF(T:T,"Rendah",M:M) -> 46423250
A28: ORD00466 | B28: 45912.146 | C28: Ani Hidayat | D28: Samarinda | E28: Bawang Merah - Brand A | F28: 30000 | G28: 1 | H28: 0 | I28: =F28*G28 -> 30000 | J28: =I28*H28/100 -> 0 | K28: =I28-J28 -> 30000 | L28: 0 | M28: =Table1[[#This Row],[Total Sales]]+Table1[[#This Row],[Shipping Fee]] -> 30000 | N28: e-Wallet | O28: =VLOOKUP(Table1[[#This Row],[Order ID]],Status!A:B, 2,FALSE) -> Completed | P28: TokTok | Q28: 5 | R28: Perempuan | S28: =_xlfn.IFS(Q28>3,"Bagus",Q28=3,"Standar",Q28<3,"Rendah") -> Bagus | T28: =_xlfn.IFS(J28<=5000,"Sangat Rendah", J28<=10000,"Rendah", J28<=20000, "Normal", J28<=35000, "Tinggi", J28<= 50000, "Sangat Tinggi", J28>50000, "Clearance") -> Sangat Rendah
A29: ORD00610 | B29: 45911.31 | C29: Ani Utami | D29: Banjarbaru | E29: Garam - Brand A | F29: 4000 | G29: 2 | H29: 5 | I29: =F29*G29 -> 8000 | J29: =I29*H29/100 -> 400 | K29: =I29-J29 -> 7600 | L29: 55000 | M29: =Table1[[#This Row],[Total Sales]]+Table1[[#This Row],[Shipping Fee]] -> 62600 | N29: Kartu Kredit | O29: =VLOOKUP(Table1[[#This Row],[Order ID]],Status!A:B, 2,FALSE) -> Completed | P29: Toko Orange | Q29: 2 | R29: Perempuan | S29: =_xlfn.IFS(Q29>3,"Bagus",Q29=3,"Standar",Q29<3,"Rendah") -> Rendah | T29: =_xlfn.IFS(J29<=5000,"Sangat Rendah", J29<=10000,"Rendah", J29<=20000, "Normal", J29<=35000, "Tinggi", J29<= 50000, "Sangat Tinggi", J29>50000, "Clearance") -> Sangat Rendah
A30: ORD01002 | B30: 45910.487 | C30: Yani Santoso | D30: Pontianak | E30: Telur Ayam - Brand C | F30: 28000 | G30: 5 | H30: 15 | I30: =F30*G30 -> 140000 | J30: =I30*H30/100 -> 21000 | K30: =I30-J30 -> 119000 | L30: 85000 | M30: =Table1[[#This Row],[Total Sales]]+Table1[[#This Row],[Shipping Fee]] -> 204000 | N30: e-Wallet | O30: =VLOOKUP(Table1[[#This Row],[Order ID]],Status!A:B, 2,FALSE) -> Pending | P30: Toko Orange | Q30: 4 | R30: Perempuan | S30: =_xlfn.IFS(Q30>3,"Bagus",Q30=3,"Standar",Q30<3,"Rendah") -> Bagus | T30: =_xlfn.IFS(J30<=5000,"Sangat Rendah", J30<=10000,"Rendah", J30<=20000, "Normal", J30<=35000, "Tinggi", J30<= 50000, "Sangat Tinggi", J30>50000, "Clearance") -> Tinggi | X30: Rata-rata customer rating perempuan kategori sangat tinggi
A31: ORD00708 | B31: 45910.324 | C31: Zahra Saputra | D31: Palembang | E31: Telur Ayam - Brand C | F31: 28000 | G31: 1 | H31: 10 | I31: =F31*G31 -> 28000 | J31: =I31*H31/100 -> 2800 | K31: =I31-J31 -> 25200 | L31: 17000 | M31: =Table1[[#This Row],[Total Sales]]+Table1[[#This Row],[Shipping Fee]] -> 42200 | N31: COD | O31: =VLOOKUP(Table1[[#This Row],[Order ID]],Status!A:B, 2,FALSE) -> Cancelled | P31: Toko Biru | Q31: 3 | R31: Perempuan | S31: =_xlfn.IFS(Q31>3,"Bagus",Q31=3,"Standar",Q31<3,"Rendah") -> Standar | T31: =_xlfn.IFS(J31<=5000,"Sangat Rendah", J31<=10000,"Rendah", J31<=20000, "Normal", J31<=35000, "Tinggi", J31<= 50000, "Sangat Tinggi", J31>50000, "Clearance") -> Sangat Rendah | X31: =AVERAGEIFS(Q:Q,R:R,"Perempuan",T:T,"Sangat Tinggi") -> 3.0416667
A32: ORD00389 | B32: 45910.002 | C32: Dina Puspita | D32: Bandung | E32: Garam - Brand A | F32: 4000 | G32: 1 | H32: 0 | I32: =F32*G32 -> 4000 | J32: =I32*H32/100 -> 0 | K32: =I32-J32 -> 4000 | L32: 0 | M32: =Table1[[#This Row],[Total Sales]]+Table1[[#This Row],[Shipping Fee]] -> 4000 | N32: Kartu Kredit | O32: =VLOOKUP(Table1[[#This Row],[Order ID]],Status!A:B, 2,FALSE) -> Completed | P32: Toko Hijau | Q32: 2 | R32: Perempuan | S32: =_xlfn.IFS(Q32>3,"Bagus",Q32=3,"Standar",Q32<3,"Rendah") -> Rendah | T32: =_xlfn.IFS(J32<=5000,"Sangat Rendah", J32<=10000,"Rendah", J32<=20000, "Normal", J32<=35000, "Tinggi", J32<= 50000, "Sangat Tinggi", J32>50000, "Clearance") -> Sangat Rendah
A33: ORD00389 | B33: 45910.002 | C33: Dina Puspita | D33: Bandung | E33: Garam - Brand A | F33: 4000 | G33: 2 | H33: 15 | I33: =F33*G33 -> 8000 | J33: =I33*H33/100 -> 1200 | K33: =I33-J33 -> 6800 | L33: 0 | M33: =Table1[[#This Row],[Total Sales]]+Table1[[#This Row],[Shipping Fee]] -> 6800 | N33: Kartu Kredit | O33: =VLOOKUP(Table1[[#This Row],[Order ID]],Status!A:B, 2,FALSE) -> Completed | P33: Toko Hijau | Q33: 2 | R33: Perempuan | S33: =_xlfn.IFS(Q33>3,"Bagus",Q33=3,"Standar",Q33<3,"Rendah") -> Rendah | T33: =_xlfn.IFS(J33<=5000,"Sangat Rendah", J33<=10000,"Rendah", J33<=20000, "Normal", J33<=35000, "Tinggi", J33<= 50000, "Sangat Tinggi", J33>50000, "Clearance") -> Sangat Rendah
A34: ORD01049 | B34: 45909.899 | C34: Umar Setiawan | D34: Bengkulu | E34: Telur Ayam - Brand C | F34: 28000 | G34: 2 | H34: 5 | I34: =F34*G34 -> 56000 | J34: =I34*H34/100 -> 2800 | K34: =I34-J34 -> 53200 | L34: 72000 | M34: =Table1[[#This Row],[Total Sales]]+Table1[[#This Row],[Shipping Fee]] -> 125200 | N34: e-Wallet | O34: =VLOOKUP(Table1[[#This Row],[Order ID]],Status!A:B, 2,FALSE) -> Completed | P34: TokTok | Q34: 1 | R34: Laki-laki | S34: =_xlfn.IFS(Q34>3,"Bagus",Q34=3,"Standar",Q34<3,"Rendah") -> Rendah | T34: =_xlfn.IFS(J34<=5000,"Sangat Rendah", J34<=10000,"Rendah", J34<=20000, "Normal", J34<=35000, "Tinggi", J34<= 50000, "Sangat Tinggi", J34>50000, "Clearance") -> Sangat Rendah
A35: ORD00629 | B35: 45909.625 | C35: Ani Ramadhani | D35: Sofifi | E35: Gula Pasir - Brand A | F35: 16000 | G35: 3 | H35: 20 | I35: =F35*G35 -> 48000 | J35: =I35*H35/100 -> 9600 | K35: =I35-J35 -> 38400 | L35: 50000 | M35: =Table1[[#This Row],[Total Sales]]+Table1[[#This Row],[Shipping Fee]] -> 88400 | N35: e-Wallet | O35: =VLOOKUP(Table1[[#This Row],[Order ID]],Status!A:B, 2,FALSE) -> Pending | P35: Toko Orange | Q35: 4 | R35: Perempuan | S35: =_xlfn.IFS(Q35>3,"Bagus",Q35=3,"Standar",Q35<3,"Rendah") -> Bagus | T35: =_xlfn.IFS(J35<=5000,"Sangat Rendah", J35<=10000,"Rendah", J35<=20000, "Normal", J35<=35000, "Tinggi", J35<= 50000, "Sangat Tinggi", J35>50000, "Clearance") -> Rendah
A36: ORD00731 | B36: 45909.472 | C36: Vina Iskandar | D36: Manokwari | E36: Garam - Brand C | F36: 6000 | G36: 4 | H36: 10 | I36: =F36*G36 -> 24000 | J36: =I36*H36/100 -> 2400 | K36: =I36-J36 -> 21600 | L36: 18000 | M36: =Table1[[#This Row],[Total Sales]]+Table1[[#This Row],[Shipping Fee]] -> 39600 | N36: Kartu Kredit | O36: =VLOOKUP(Table1[[#This Row],[Order ID]],Status!A:B, 2,FALSE) -> Completed | P36: TokTok | Q36: 1 | R36: Perempuan | S36: =_xlfn.IFS(Q36>3,"Bagus",Q36=3,"Standar",Q36<3,"Rendah") -> Rendah | T36: =_xlfn.IFS(J36<=5000,"Sangat Rendah", J36<=10000,"Rendah", J36<=20000, "Normal", J36<=35000, "Tinggi", J36<= 50000, "Sangat Tinggi", J36>50000, "Clearance") -> Sangat Rendah
A37: ORD00527 | B37: 45909.465 | C37: Fitri Halim | D37: Denpasar | E37: Telur Ayam - Brand B | F37: 25000 | G37: 4 | H37: 5 | I37: =F37*G37 -> 100000 | J37: =I37*H37/100 -> 5000 | K37: =I37-J37 -> 95000 | L37: 80000 | M37: =Table1[[#This Row],[Total Sales]]+Table1[[#This Row],[Shipping Fee]] -> 175000 | N37: Transfer Bank | O37: =VLOOKUP(Table1[[#This Row],[Order ID]],Status!A:B, 2,FALSE) -> Completed | P37: TokTok | Q37: 5 | R37: Perempuan | S37: =_xlfn.IFS(Q37>3,"Bagus",Q37=3,"Standar",Q37<3,"Rendah") -> Bagus | T37: =_xlfn.IFS(J37<=5000,"Sangat Rendah", J37<=10000,"Rendah", J37<=20000, "Normal", J37<=35000, "Tinggi", J37<= 50000, "Sangat Tinggi", J37>50000, "Clearance") -> Sangat Rendah
A38: ORD00176 | B38: 45909.125 | C38: Fitri Santoso | D38: Pekanbaru | E38: Beras - Brand B | F38: 15000 | G38: 2 | H38: 15 | I38: =F38*G38 -> 30000 | J38: =I38*H38/100 -> 4500 | K38: =I38-J38 -> 25500 | L38: 49000 | M38: =Table1[[#This Row],[Total Sales]]+Table1[[#This Row],[Shipping Fee]] -> 74500 | N38: Transfer Bank | O38: =VLOOKUP(Table1[[#This Row],[Order ID]],Status!A:B, 2,FALSE) -> Completed | P38: TokTok | Q38: 3 | R38: Perempuan | S38: =_xlfn.IFS(Q38>3,"Bagus",Q38=3,"Standar",Q38<3,"Rendah") -> Standar | T38: =_xlfn.IFS(J38<=5000,"Sangat Rendah", J38<=10000,"Rendah", J38<=20000, "Normal", J38<=35000, "Tinggi", J38<= 50000, "Sangat Tinggi", J38>50000, "Clearance") -> Sangat Rendah
A39: ORD00154 | B39: 45908.993 | C39: Hana Pradipta | D39: Jayapura | E39: Gula Pasir - Brand A | F39: 16000 | G39: 1 | H39: 0 | I39: =F39*G39 -> 16000 | J39: =I39*H39/100 -> 0 | K39: =I39-J39 -> 16000 | L39: 30000 | M39: =Table1[[#This Row],[Total Sales]]+Table1[[#This Row],[Shipping Fee]] -> 46000 | N39: Kartu Kredit | O39: =VLOOKUP(Table1[[#This Row],[Order ID]],Status!A:B, 2,FALSE) -> Cancelled | P39: Toko Biru | Q39: 4 | R39: Perempuan | S39: =_xlfn.IFS(Q39>3,"Bagus",Q39=3,"Standar",Q39<3,"Rendah") -> Bagus | T39: =_xlfn.IFS(J39<=5000,"Sangat Rendah", J39<=10000,"Rendah", J39<=20000, "Normal", J39<=35000, "Tinggi", J39<= 50000, "Sangat Tinggi", J39>50000, "Clearance") -> Sangat Rendah
A40: ORD00902 | B40: 45908.258 | C40: Hana Setiawan | D40: Mataram | E40: Beras - Brand C | F40: 16000 | G40: 2 | H40: 10 | I40: =F40*G40 -> 32000 | J40: =I40*H40/100 -> 3200 | K40: =I40-J40 -> 28800 | L40: 56000 | M40: =Table1[[#This Row],[Total Sales]]+Table1[[#This Row],[Shipping Fee]] -> 84800 | N40: COD | O40: =VLOOKUP(Table1[[#This Row],[Order ID]],Status!A:B, 2,FALSE) -> Completed | P40: Toko Ungu | Q40: 2 | R40: Perempuan | S40: =_xlfn.IFS(Q40>3,"Bagus",Q40=3,"Standar",Q40<3,"Rendah") -> Rendah | T40: =_xlfn.IFS(J40<=5000,"Sangat Rendah", J40<=10000,"Rendah", J40<=20000, "Normal", J40<=35000, "Tinggi", J40<= 50000, "Sangat Tinggi", J40>50000, "Clearance") -> Sangat Rendah
...

Sheet Status
A1: Order ID | B1: Order Status
A2: ORD00001 | B2: Returned
A3: ORD00002 | B3: Completed
A4: ORD00003 | B4: Returned
A5: ORD00004 | B5: Shipped
A6: ORD00005 | B6: Cancelled
A7: ORD00006 | B7: Completed
A8: ORD00007 | B8: Completed
A9: ORD00008 | B9: Returned
A10: ORD00009 | B10: Completed
A11: ORD00010 | B11: Completed
A12: ORD00011 | B12: Completed
... A1867: ORD01866 | B1867: Completed

Sheet Day2
A3: Row Labels | B3: Sum of Quantity | C3: Sum of Grand Total
A4: Clearance | B4: 10 | C4: 592000
A5: Normal | B5: 1105 | C5: 41454500
A6: Rendah | B6: 1207 | C6: 46423250 | E6: =AVERAGE(C4:C9) -> 38589675 | F6: <- Rata-rata
A7: Sangat Rendah | B7: 2896 | C7: 108161000
A8: Sangat Tinggi | B8: 128 | C8: 6526750
A9: Tinggi | B9: 585 | C9: 28380550
A10: Grand Total | B10: 5931 | C10: 231538050

Sheet Day 3
A3: Row Labels | B3: Sum of Discount Amount | E3: Row Labels | F3: Average of Shipping Fee | I3: Sum of Grand Total | J3: Column Labels
A4: COD | B4: 3553450 | E4: Ambon | F4: 46772.727 | I4: Row Labels | J4: Cancelled | K4: Completed | L4: Pending | M4: Returned | N4: Shipped | O4: Grand Total
A5: e-Wallet | B5: 3200600 | E5: Banda Aceh | F5: 17647.059 | I5: Toko Biru | J5: 2518900 | K5: 34287150 | L5: 1864100 | M5: 6209750 | N5: 1166550 | O5: 46046450
A6: Kartu Kredit | B6: 3385200 | E6: Bandar Lampung | F6: 26444.444 | I6: Toko Hijau | J6: 3631500 | K6: 34824650 | L6: 1231150 | M6: 5833300 | N6: 1054000 | O6: 46574600
A7: Transfer Bank | B7: 3700700 | E7: Bandung | F7: 0 | I7: Toko Orange | J7: 2679950 | K7: 33355800 | L7: 1077400 | M7: 6535350 | N7: 1334050 | O7: 44982550
A8: Grand Total | B8: 13839950 | E8: Banjarbaru | F8: 52659.574 | I8: Toko Ungu | J8: 1519900 | K8: 35524650 | L8: 2506550 | M8: 5826500 | N8: 2100050 | O8: 47477650
E9: Bengkulu | F9: 70779.661 | I9: TokTok | J9: 2196000 | K9: 33457100 | L9: 1485200 | M9: 8585750 | N9: 732750 | O9: 46456800
E10: Denpasar | F10: 80000 | I10: Grand Total | J10: 12546250 | K10: 171449350 | L10: 8164400 | M10: 32990650 | N10: 6387400 | O10: 231538050
E11: Gorontalo | F11: 74074.074
E12: Jakarta | F12: 86640.777
E13: Jambi | F13: 83297.872
E14: Jayapura | F14: 28750
E15: Kendari | F15: 52789.474 | I15: Row Labels | J15: Average of Customer Rating | M15: Row Labels | N15: Sum of Grand Total
E16: Kupang | F16: 21000 | I16: Laki-laki | J16: 3.0275689 | M16: Susu Bubuk - Brand C | N16: 14914750
E17: Makassar | F17: 81529.412 | I17: Normal | J17: 2.8356164 | M17: Daging Ayam - Brand C | N17: 14698500
E18: Mamuju | F18: 43513.514 | I18: Rendah | J18: 3.3 | M18: Susu Bubuk - Brand B | N18: 14227000
E19: Manado | F19: 84348.837 | I19: Sangat Rendah | J19: 2.9953488 | M19: Daging Ayam - Brand B | N19: 14041000
E20: Manokwari | F20: 16524.59 | I20: Sangat Tinggi | J20: 2.3333333 | M20: Susu Bubuk - Brand A | N20: 12372750
E21: Mataram | F21: 53052.632 | I21: Tinggi | J21: 3.0714286 | M21: Bawang Merah - Brand B | N21: 10556750
E22: Medan | F22: 74260 | I22: Perempuan | J22: 2.9687695 | M22: Daging Ayam - Brand A | N22: 10336000
E23: Merauke | F23: 56640 | I23: Clearance | J23: 3 | M23: Telur Ayam - Brand C | N23: 9824600
E24: Nabire | F24: 86880.952 | I24: Normal | J24: 3.0409091 | M24: Telur Ayam - Brand B | N24: 9050750
E25: Padang | F25: 65384.615 | I25: Rendah | J25: 2.9111111 | M25: Telur Ayam - Brand A | N25: 8890000
E26: Palangka Raya | F26: 47222.222 | I26: Sangat Rendah | J26: 2.9686147 | M26: Grand Total | N26: 118912100
E27: Palembang | F27: 17000 | I27: Sangat Tinggi | J27: 3.0416667
E28: Palu | F28: 59555.556 | I28: Tinggi | J28: 2.9741379
E29: Pangkalpinang | F29: 15868.421 | I29: Grand Total | J29: 2.9805
E30: Pekanbaru | F30: 44625
E31: Pontianak | F31: 79407.895
E32: Samarinda | F32: 38700
E33: Semarang | F33: 64823.529
E34: Serang | F34: 55218.75
E35: Sofifi | F35: 47435.897
E36: Sorong | F36: 82721.311
E37: Surabaya | F37: 65236.842
E38: Tanjung Selor | F38: 24142.857
E39: Tanjungpinang | F39: 44129.032
E40: Wamena | F40: 13828.125
E41: Yogyakarta | F41: 75562.5
E42: Grand Total | F42: 51525.5

Sheet dash
A3: Row Labels | B3: Sum of Grand Total | D3: Row Labels | E3: Sum of Quantity | G3: Row Labels | H3: Count of Order ID
A4: Transfer Bank | B4: 59977300 | D4: Garam - Brand C | E4: 267 | G4: 2024 | H4: 570
A5: Grand Total | B5: 59977300 | D5: Daging Ayam - Brand B | E5: 259 | G5: Sep | H5: 97
D6: Tepung Terigu - Brand C | E6: 254 | G6: Oct | H6: 159
D7: Daging Ayam - Brand C | E7: 250 | G7: Nov | H7: 156
D8: Minyak Goreng - Brand A | E8: 247 | G8: Dec | H8: 158
D9: Telur Ayam - Brand B | E9: 247 | G9: 2025 | H9: 1430
D10: Gula Pasir - Brand C | E10: 238 | G10: Jan | H10: 172
D11: Telur Ayam - Brand A | E11: 235 | G11: Feb | H11: 138
D12: Susu Bubuk - Brand B | E12: 229 | G12: Mar | H12: 155
D13: Telur Ayam - Brand C | E13: 224 | G13: Apr | H13: 156
D14: Susu Bubuk - Brand C | E14: 224 | G14: May | H14: 181
D15: Gula Pasir - Brand A | E15: 221 | G15: Jun | H15: 185
D16: Garam - Brand A | E16: 220 | G16: Jul | H16: 189
D17: Beras - Brand A | E17: 219 | G17: Aug | H17: 165
... D19: Minyak Goreng - Brand B | E19: 216 | G19: Grand Total | H19: 2000
D20: Bawang Merah - Brand B | E20: 215
D21: Beras - Brand B | E21: 212
D22: Daging Ayam - Brand A | E22: 210
D23: Tepung Terigu - Brand B | E23: 208
D24: Tepung Terigu - Brand A | E24: 205
D25: Gula Pasir - Brand B | E25: 205
D26: Garam - Brand B | E26: 203
D27: Bawang Merah - Brand A | E27: 194
D28: Beras - Brand C | E28: 193
D29: Minyak Goreng - Brand C | E29: 171
D30: Bawang Merah - Brand C | E30: 146
D31: Grand Total | E31: 5931

Sheet DASHBOARD
